Workbook

Sheet Cover
B2: Valuation of Industry Peers — FMCG Sector (India)
B3: Relative Valuation & 3-Statement Financial Model — Britannia Industries Ltd (Target)
B4: Prepared: July 2026 | Currency: INR Crores unless stated | Fiscal Year End: March
B6: Scope
B7: Relative valuation of 7 listed FMCG companies (EV/EBITDA, P/E, P/B) benchmarked against peer averages; a 5-year 3-statement financial model and DCF for Britannia Industries Ltd (target company); sensitivity testing on WACC and terminal growth.
B11: Peer Set (Sector: FMCG — India)
B12: Britannia Industries Ltd | D12: BRITANNIA | E12: Packaged Foods (Biscuits/Bakery) — TARGET COMPANY
B13: Hindustan Unilever Ltd | D13: HINDUNILVR | E13: Diversified FMCG (Home/Personal Care, Foods)
B14: ITC Ltd | D14: ITC | E14: Diversified FMCG (Cigarettes, Foods, Personal Care)
B15: Nestlé India Ltd | D15: NESTLEIND | E15: Packaged Foods & Beverages
B16: Dabur India Ltd | D16: DABUR | E16: Personal Care / Ayurvedic FMCG
B17: Godrej Consumer Products Ltd | D17: GODREJCP | E17: Personal & Home Care
B18: Marico Ltd | D18: MARICO | E18: Personal Care / Edible Oils
B21: Contents
B22: 1. Comps — Comparable Company Analysis (EV/EBITDA, P/E, P/B)
B23: 2. 3-Statement Model — Britannia Industries (FY24A-FY26A, FY27E-FY31E)
B24: 3. DCF Valuation — 5-Year FCF Projection + Terminal Value
B25: 4. Sensitivity — WACC x Terminal Growth Rate (implied share price)
B26: 5. Valuation Summary & Conclusion
B29: Data sources
B30: Company financials (FY24-FY26 actuals): Screener.in, compiled from company audited consolidated financial statements filed with BSE/NSE. Market data (price, market cap, P/E, P/B) as of early-June 2026 close. All figures in ₹ Crores unless noted. Blue = hardcoded/sourced inputs; Black = formulas; Green = cross-sheet links.

Sheet Comps
B2: Comparable Company Analysis — Indian FMCG Sector
B3: FY2026 (year ended Mar-2026) actuals; market data as of early-June 2026. ₹ Crores except per-share and ratios.
B6: Company | C6: Revenue | D6: EBITDA* | E6: EBITDA Margin | F6: Net Profit | G6: Net Margin | H6: EPS (₹) | I6: Shares (Cr) | J6: Market Cap | K6: Net Debt** | L6: EV | M6: EV/ EBITDA | N6: P/E | O6: Book Val/ Share (₹) | P6: P/B | Q6: ROE
B7: Britannia Industries | C7: 19152 | D7: 3514 | E7: =D7/C7 -> 0.18347953 | F7: 2537 | G7: =F7/C7 -> 0.13246658 | H7: 105.18 | I7: 24 | J7: 124537 | K7: =1380-3610 -> -2230 | L7: =J7+K7 -> 122307 | M7: =L7/D7 -> 34.805635 | N7: =J7/F7 -> 49.088293 | O7: 212 | P7: =(J7/I7)/O7 -> 24.476612 | Q7: 0.536
B8: Hindustan Unilever | C8: 64468 | D8: 15039 | E8: =D8/C8 -> 0.23327853 | F8: 15059 | G8: =F8/C8 -> 0.23358876 | H8: 64.01 | I8: 235.3 | J8: 509961 | K8: =1478-4359 -> -2881 | L8: =J8+K8 -> 507080 | M8: =L8/D8 -> 33.717667 | N8: =J8/F8 -> 33.864201 | O8: 207 | P8: =(J8/I8)/O8 -> 10.469952 | Q8: 0.31
B9: ITC Ltd | C9: 78868 | D9: 27318 | E9: =D9/C9 -> 0.34637622 | F9: 21018 | G9: =F9/C9 -> 0.26649592 | H9: 16.51 | I9: 1253 | J9: 355462 | K9: =2399-38128 -> -35729 | L9: =J9+K9 -> 319733 | M9: =L9/D9 -> 11.704115 | N9: =J9/F9 -> 16.912266 | O9: 57.9 | P9: =(J9/I9)/O9 -> 4.8996329 | Q9: 0.293
B10: Nestle India | C10: 23155 | D10: 5307 | E10: =D10/C10 -> 0.22919456 | F10: 3545 | G10: =F10/C10 -> 0.15309868 | H10: 18.38 | I10: 192.8 | J10: 277240 | K10: =444-706 -> -262 | L10: =J10+K10 -> 276978 | M10: =L10/D10 -> 52.191068 | N10: =J10/F10 -> 78.205924 | O10: 27.5 | P10: =(J10/I10)/O10 -> 52.289702 | Q10: 0.732
B11: Dabur India | C11: 13193 | D11: 2450 | E11: =D11/C11 -> 0.18570454 | F11: 1869 | G11: =F11/C11 -> 0.14166604 | H11: 10.68 | I11: 177 | J11: 75384 | K11: =1287-8947 -> -7660 | L11: =J11+K11 -> 67724 | M11: =L11/D11 -> 27.642449 | N11: =J11/F11 -> 40.333868 | O11: 64.4 | P11: =(J11/I11)/O11 -> 6.6133277 | Q11: 0.172
B12: Godrej Consumer | C12: 15178 | D12: 3189 | E12: =D12/C12 -> 0.21010673 | F12: 1861 | G12: =F12/C12 -> 0.12261167 | H12: 18.07 | I12: 103 | J12: 105865 | K12: =700-0 -> 700 | L12: =J12+K12 -> 106565 | M12: =L12/D12 -> 33.416431 | N12: =J12/F12 -> 56.886083 | O12: 122.8 | P12: =(J12/I12)/O12 -> 8.3698333 | Q12: n/a
B13: Marico Ltd | C13: 13611 | D13: 2586 | E13: =D13/C13 -> 0.18999339 | F13: 1813 | G13: =F13/C13 -> 0.13320109 | H13: 15.6 | I13: 116.22 | J13: 108578 | K13: =900-0 -> 900 | L13: =J13+K13 -> 109478 | M13: =L13/D13 -> 42.33488 | N13: =J13/F13 -> 59.888582 | O13: n/a | P13: n/a | Q13: n/a
B15: Peer Average (ex-Britannia) | E15: =AVERAGE(E8:E13) -> 0.23244233 | G15: =AVERAGE(G8:G13) -> 0.17511036 | M15: =AVERAGE(M8:M13) -> 33.501102 | N15: =AVERAGE(N8:N13) -> 47.681821 | P15: =AVERAGE(P8:P13) -> 16.52849 | Q15: =AVERAGE(Q8:Q13) -> 0.37675
B16: Peer Median (ex-Britannia) | E16: =MEDIAN(E8:E13) -> 0.21965065 | G16: =MEDIAN(G8:G13) -> 0.14738236 | M16: =MEDIAN(M8:M13) -> 33.567049 | N16: =MEDIAN(N8:N13) -> 48.609976 | P16: =MEDIAN(P8:P13) -> 8.3698333 | Q16: =MEDIAN(Q8:Q13) -> 0.3015
B18: Notes:
B19: • * EBITDA proxied by reported Operating Profit (pre-interest, pre-tax, pre-D&A per Screener.in convention).
B20: • ** Net Debt = Total Borrowings − Investments (cash/liquid investments proxy). Negative = net cash position.
B21: • Godrej Consumer & Marico EBITDA estimated from disclosed operating margins in recent quarterly commentary (~21% and ~19% respectively); flagged as estimates.
B22: • All figures are consolidated, FY2026 (year ended 31-Mar-2026), sourced from Screener.in (compiled from company filings). Market data as of early-June 2026.

Sheet 3-Statement Model
B2: Britannia Industries Ltd — 3-Statement Financial Model (₹ Crores)
B3: FY24A-FY26A actuals (Screener.in); FY27E-FY31E projected on assumptions below
C5: FY2024A | D5: FY2025A | E5: FY2026A | F5: FY2027E | G5: FY2028E | H5: FY2029E | I5: FY2030E | J5: FY2031E
B7: KEY ASSUMPTIONS (projection years only)
B8: Revenue growth % | F8: 0.09 | G8: 0.09 | H8: 0.08 | I8: 0.08 | J8: 0.07
B9: EBITDA margin % | F9: 0.185 | G9: 0.19 | H9: 0.19 | I9: 0.195 | J9: 0.195
B10: Tax rate % | F10: 0.24 | G10: 0.24 | H10: 0.245 | I10: 0.245 | J10: 0.245
B11: D&A (% of revenue) | F11: 0.017 | G11: 0.017 | H11: 0.017 | I11: 0.017 | J11: 0.017
B12: Capex (% of revenue) | F12: 0.022 | G12: 0.022 | H12: 0.022 | I12: 0.022 | J12: 0.022
B13: Net working capital (% of revenue) | F13: -0.023 | G13: -0.023 | H13: -0.023 | I13: -0.023 | J13: -0.023
B14: Interest expense (% of avg borrowings) | F14: 0.075 | G14: 0.075 | H14: 0.075 | I14: 0.075 | J14: 0.075
B15: Dividend payout ratio % | F15: 0.84 | G15: 0.84 | H15: 0.84 | I15: 0.84 | J15: 0.84
B17: NOTE: Cells highlighted in yellow are editable assumptions — change them to re-run the model / sensitivity.
B19: INCOME STATEMENT
B20: Revenue | C20: 16769 | D20: 17943 | E20: 19152 | F20: =E20*(1+F8) -> 20875.68 | G20: =F20*(1+G8) -> 22754.491 | H20: =G20*(1+H8) -> 24574.85 | I20: =H20*(1+I8) -> 26540.839 | J20: =I20*(1+J8) -> 28398.697
B21: Revenue growth % | D21: =D20/C20-1 -> 0.070010138 | E21: =E20/D20-1 -> 0.067380037 | F21: =F20/E20-1 -> 0.09 | G21: =G20/F20-1 -> 0.09 | H21: =H20/G20-1 -> 0.08 | I21: =I20/H20-1 -> 0.08 | J21: =J20/I20-1 -> 0.07
B22: EBITDA | C22: 3167 | D22: 3176 | E22: 3514 | F22: =F20*F9 -> 3862.0008 | G22: =G20*G9 -> 4323.3533 | H22: =H20*H9 -> 4669.2216 | I22: =I20*I9 -> 5175.4635 | J22: =J20*J9 -> 5537.746
B23: EBITDA margin % | C23: =C22/C20 -> 0.1888604 | D23: =D22/D20 -> 0.17700496 | E23: =E22/E20 -> 0.18347953 | F23: =F22/F20 -> 0.185 | G23: =G22/G20 -> 0.19 | H23: =H22/H20 -> 0.19 | I23: =I22/I20 -> 0.195 | J23: =J22/J20 -> 0.195
B24: Less: D&A | C24: -300 | D24: -313 | E24: -337 | F24: =-F20*F11 -> -354.88656 | G24: =-G20*G11 -> -386.82635 | H24: =-H20*H11 -> -417.77246 | I24: =-I20*I11 -> -451.19426 | J24: =-J20*J11 -> -482.77785
B25: EBIT | C25: =C22+C24 -> 2867 | D25: =D22+D24 -> 2863 | E25: =E22+E24 -> 3177 | F25: =F22+F24 -> 3507.1142 | G25: =G22+G24 -> 3936.527 | H25: =H22+H24 -> 4251.4491 | I25: =I22+I24 -> 4724.2693 | J25: =J22+J24 -> 5054.9681
B26: Add: Other income | C26: 211 | D26: 202 | E26: 224 | F26: =E26 -> 224 | G26: =E26 -> 224 | H26: =E26 -> 224 | I26: =E26 -> 224 | J26: =E26 -> 224
B27: Less: Interest expense | C27: -164 | D27: -139 | E27: -113 | F27: =-F42*F14 -> -103.5 | G27: =-G42*G14 -> -103.5 | H27: =-H42*H14 -> -103.5 | I27: =-I42*I14 -> -103.5 | J27: =-J42*J14 -> -103.5
B28: PBT (Profit Before Tax) | C28: =C25+C26+C27 -> 2914 | D28: =D25+D26+D27 -> 2926 | E28: =E25+E26+E27 -> 3288 | F28: =F25+F26+F27 -> 3627.6142 | G28: =G25+G26+G27 -> 4057.027 | H28: =H25+H26+H27 -> 4371.9491 | I28: =I25+I26+I27 -> 4844.7693 | J28: =J25+J26+J27 -> 5175.4681
B29: Less: Tax | C29: -786 | D29: -749 | E29: -752 | F29: =-F28*F10 -> -870.62742 | G29: =-G28*G10 -> -973.68647 | H29: =-H28*H10 -> -1071.1275 | I29: =-I28*I10 -> -1186.9685 | J29: =-J28*J10 -> -1267.9897
B30: Net Income | C30: =C28+C29 -> 2128 | D30: =D28+D29 -> 2177 | E30: =E28+E29 -> 2536 | F30: =F28+F29 -> 2756.9868 | G30: =G28+G29 -> 3083.3405 | H30: =H28+H29 -> 3300.8216 | I30: =I28+I29 -> 3657.8008 | J30: =J28+J29 -> 3907.4784
B31: Net margin % | C31: =C30/C20 -> 0.12690083 | D31: =D30/D20 -> 0.12132865 | E31: =E30/E20 -> 0.13241437 | F31: =F30/F20 -> 0.13206692 | G31: =G30/G20 -> 0.1355047 | H31: =H30/H20 -> 0.13431706 | I31: =I30/I20 -> 0.13781783 | J31: =J30/J20 -> 0.13759358
B33: BALANCE SHEET (SIMPLIFIED)
B34: Net Fixed Assets (opening) | C34: n/a | D34: 2771 | E34: 2904 | F34: =E37 -> 2850 | G34: =F37 -> 2954.3784 | H34: =G37 -> 3068.1509 | I34: =H37 -> 3191.0251 | J34: =I37 -> 3323.7293
B35: Add: Capex | C35: n/a | D35: 188 | E35: 89 | F35: =F20*F12 -> 459.26496 | G35: =G20*G12 -> 500.59881 | H35: =H20*H12 -> 540.64671 | I35: =I20*I12 -> 583.89845 | J35: =J20*J12 -> 624.77134
B36: Less: D&A | C36: n/a | D36: -313 | E36: -337 | F36: =F24 -> -354.88656 | G36: =G24 -> -386.82635 | H36: =H24 -> -417.77246 | I36: =I24 -> -451.19426 | J36: =J24 -> -482.77785
B37: Net Fixed Assets (closing) | C37: 2655 | D37: =D34+D35+D36 -> 2646 | E37: 2850 | F37: =F34+F35+F36 -> 2954.3784 | G37: =G34+G35+G36 -> 3068.1509 | H37: =H34+H35+H36 -> 3191.0251 | I37: =I34+I35+I36 -> 3323.7293 | J37: =J34+J35+J36 -> 3465.7228
B38: Investments (held constant) | C38: 3324 | D38: 2767 | E38: 3610 | F38: =E38 -> 3610 | G38: =E38 -> 3610 | H38: =E38 -> 3610 | I38: =E38 -> 3610 | J38: =E38 -> 3610
B39: Net Working Capital | C39: =C20*C13 -> 0 | D39: =D20*D13 -> 0 | E39: =E20*E13 -> 0 | F39: =F20*F13 -> -480.14064 | G39: =G20*G13 -> -523.3533 | H39: =H20*H13 -> -565.22156 | I39: =I20*I13 -> -610.43929 | J39: =J20*J13 -> -653.17004
B40: Cash & Cash Equivalents (plug) | C40: n/a | D40: =D45-D37-D38-D39 -> 3425 | E40: =E45-E37-E38-E39 -> 3271 | F40: =F45-F37-F38-F39 -> 4379.9301 | G40: =G45-G37-G38-G39 -> 5121.0393 | H40: =H45-H37-H38-H39 -> 5876.5955 | I40: =I45-I37-I38-I39 -> 6707.4624 | J40: =J45-J37-J38-J39 -> 7548.1807
B41: Total Assets | C41: =SUM(C37,C38,C39,C40) -> 5979 | D41: =SUM(D37,D38,D39,D40) -> 8838 | E41: =SUM(E37,E38,E39,E40) -> 9731 | F41: =SUM(F37,F38,F39,F40) -> 10464.168 | G41: =SUM(G37,G38,G39,G40) -> 11275.837 | H41: =SUM(H37,H38,H39,H40) -> 12112.399 | I41: =SUM(I37,I38,I39,I40) -> 13030.752 | J41: =SUM(J37,J38,J39,J40) -> 13970.733
B42: Borrowings (held constant) | C42: 2065 | D42: 1247 | E42: 1380 | F42: =E42 -> 1380 | G42: =E42 -> 1380 | H42: =E42 -> 1380 | I42: =E42 -> 1380 | J42: =E42 -> 1380
B43: Other Liabilities (% of revenue) | C43: 3065 | D43: 3235 | E43: 3245 | F43: =F20*(E43/E20) -> 3537.05 | G43: =G20*(E43/E20) -> 3855.3845 | H43: =H20*(E43/E20) -> 4163.8153 | I43: =I20*(E43/E20) -> 4496.9205 | J43: =J20*(E43/E20) -> 4811.7049
B44: Shareholders' Equity (closing) | C44: 3941 | D44: 4356 | E44: 5106 | F44: =E44+F30*(1-F15) -> 5547.1179 | G44: =F44+G30*(1-G15) -> 6040.4524 | H44: =G44+H30*(1-H15) -> 6568.5838 | I44: =H44+I30*(1-I15) -> 7153.832 | J44: =I44+J30*(1-J15) -> 7779.0285
B45: Total Liabilities & Equity | C45: n/a | D45: =SUM(D42,D43,D44) -> 8838 | E45: =SUM(E42,E43,E44) -> 9731 | F45: =SUM(F42,F43,F44) -> 10464.168 | G45: =SUM(G42,G43,G44) -> 11275.837 | H45: =SUM(H42,H43,H44) -> 12112.399 | I45: =SUM(I42,I43,I44) -> 13030.752 | J45: =SUM(J42,J43,J44) -> 13970.733
B47: CASH FLOW STATEMENT (SIMPLIFIED)
...

Sheet DCF Valuation
B2: Britannia Industries Ltd — DCF Valuation (5-Year FCF Horizon)
B3: Discounted Cash Flow using unlevered FCF from the 3-Statement Model + Gordon Growth terminal value
B5: VALUATION ASSUMPTIONS
B6: WACC (discount rate) | C6: 0.11
B7: Terminal growth rate (g) | C7: 0.05
B8: Shares outstanding (Cr) | C8: 24
B9: Current share price (₹) | C9: 5171
B11: FREE CASH FLOW PROJECTION (₹ Crores)
C12: FY2027E | D12: FY2028E | E12: FY2029E | F12: FY2030E | G12: FY2031E
B13: Free Cash Flow (FCF) | C13: ='3-Statement Model'!F53 -> 3132.7491 | D13: ='3-Statement Model'!G53 -> 3012.7807 | E13: ='3-Statement Model'!H53 -> 3219.8156 | F13: ='3-Statement Model'!I53 -> 3570.3143 | G13: ='3-Statement Model'!J53 -> 3808.2157
B14: Discount period (years) | C14: 1 | D14: 2 | E14: 3 | F14: 4 | G14: 5
B15: Discount factor | C15: =1/(1+C6)^C14 -> 0.9009009 | D15: =1/(1+C6)^D14 -> 0.81162243 | E15: =1/(1+C6)^E14 -> 0.73119138 | F15: =1/(1+C6)^F14 -> 0.65873097 | G15: =1/(1+C6)^G14 -> 0.59345133
B16: PV of FCF | C16: =C13*C15 -> 2822.2965 | D16: =D13*D15 -> 2445.2404 | E16: =E13*E15 -> 2354.3014 | F16: =F13*F15 -> 2351.8766 | G16: =G13*G15 -> 2259.9907
B18: TERMINAL VALUE & ENTERPRISE VALUE
B19: Terminal Year FCF (FY31E) | C19: =G13 -> 3808.2157
B20: Terminal Value = FCF x (1+g) / (WACC-g) | C20: =C19*(1+C7)/(C6-C7) -> 66643.774
B21: PV of Terminal Value | C21: =C20/(1+C6)^5 -> 39549.836
B22: Sum of PV of FCF (FY27E-FY31E) | C22: =SUM(C16:G16) -> 12233.706
B23: Enterprise Value (EV) | C23: =C22+C21 -> 51783.542
B24: % of EV from Terminal Value | C24: =C21/C23 -> 0.76375302
B26: EQUITY VALUE & IMPLIED SHARE PRICE
B27: Less: Net Debt (FY26A) | C27: ='3-Statement Model'!E42-'3-Statement Model'!E38 -> -2230
B28: Equity Value | C28: =C23-C27 -> 54013.542
B29: Shares Outstanding (Cr) | C29: =C8 -> 24
B30: Implied Value per Share (₹) | C30: =C28/C29 -> 2250.5643
B31: Current Share Price (₹) | C31: =C9 -> 5171
B32: Upside / (Downside) to DCF Value | C32: =C30/C31-1 -> -0.56477195

Sheet Sensitivity
B2: Sensitivity Analysis — Implied Share Price
B3: Implied Britannia share price (₹) under varying WACC and terminal growth rate assumptions
B5: SENSITIVITY: WACC (rows) vs. Terminal Growth Rate (columns)
B7: WACC \ Terminal g | C7: 0.03 | D7: 0.04 | E7: 0.05 | F7: 0.06 | G7: 0.07
B8: 0.09 | C8: =(SUMPRODUCT('DCF Valuation'!$C$13:$G$13,1/(1+$B8)^{1,2,3,4,5})+('DCF Valuation'!$G$13*(1+C$7))/($B8-C$7)/(1+$B8)^5-'DCF Valuation'!$C$27)/'DCF Valuation'!$C$29 -> 2400.8084 | D8: =(SUMPRODUCT('DCF Valuation'!$C$13:$G$13,1/(1+$B8)^{1,2,3,4,5})+('DCF Valuation'!$G$13*(1+D$7))/($B8-D$7)/(1+$B8)^5-'DCF Valuation'!$C$27)/'DCF Valuation'!$C$29 -> 2775.5078 | E8: =(SUMPRODUCT('DCF Valuation'!$C$13:$G$13,1/(1+$B8)^{1,2,3,4,5})+('DCF Valuation'!$G$13*(1+E$7))/($B8-E$7)/(1+$B8)^5-'DCF Valuation'!$C$27)/'DCF Valuation'!$C$29 -> 3337.557 | F8: =(SUMPRODUCT('DCF Valuation'!$C$13:$G$13,1/(1+$B8)^{1,2,3,4,5})+('DCF Valuation'!$G$13*(1+F$7))/($B8-F$7)/(1+$B8)^5-'DCF Valuation'!$C$27)/'DCF Valuation'!$C$29 -> 4274.3056 | G8: =(SUMPRODUCT('DCF Valuation'!$C$13:$G$13,1/(1+$B8)^{1,2,3,4,5})+('DCF Valuation'!$G$13*(1+G$7))/($B8-G$7)/(1+$B8)^5-'DCF Valuation'!$C$27)/'DCF Valuation'!$C$29 -> 6147.8028
B9: 0.1 | C9: =(SUMPRODUCT('DCF Valuation'!$C$13:$G$13,1/(1+$B9)^{1,2,3,4,5})+('DCF Valuation'!$G$13*(1+C$7))/($B9-C$7)/(1+$B9)^5-'DCF Valuation'!$C$27)/'DCF Valuation'!$C$29 -> 2065.9816 | D9: =(SUMPRODUCT('DCF Valuation'!$C$13:$G$13,1/(1+$B9)^{1,2,3,4,5})+('DCF Valuation'!$G$13*(1+D$7))/($B9-D$7)/(1+$B9)^5-'DCF Valuation'!$C$27)/'DCF Valuation'!$C$29 -> 2324.0236 | E9: =(SUMPRODUCT('DCF Valuation'!$C$13:$G$13,1/(1+$B9)^{1,2,3,4,5})+('DCF Valuation'!$G$13*(1+E$7))/($B9-E$7)/(1+$B9)^5-'DCF Valuation'!$C$27)/'DCF Valuation'!$C$29 -> 2685.2823 | F9: =(SUMPRODUCT('DCF Valuation'!$C$13:$G$13,1/(1+$B9)^{1,2,3,4,5})+('DCF Valuation'!$G$13*(1+F$7))/($B9-F$7)/(1+$B9)^5-'DCF Valuation'!$C$27)/'DCF Valuation'!$C$29 -> 3227.1703 | G9: =(SUMPRODUCT('DCF Valuation'!$C$13:$G$13,1/(1+$B9)^{1,2,3,4,5})+('DCF Valuation'!$G$13*(1+G$7))/($B9-G$7)/(1+$B9)^5-'DCF Valuation'!$C$27)/'DCF Valuation'!$C$29 -> 4130.317
B10: 0.11 | C10: =(SUMPRODUCT('DCF Valuation'!$C$13:$G$13,1/(1+$B10)^{1,2,3,4,5})+('DCF Valuation'!$G$13*(1+C$7))/($B10-C$7)/(1+$B10)^5-'DCF Valuation'!$C$27)/'DCF Valuation'!$C$29 -> 1815.0452 | D10: =(SUMPRODUCT('DCF Valuation'!$C$13:$G$13,1/(1+$B10)^{1,2,3,4,5})+('DCF Valuation'!$G$13*(1+D$7))/($B10-D$7)/(1+$B10)^5-'DCF Valuation'!$C$27)/'DCF Valuation'!$C$29 -> 2001.6962 | E10: =(SUMPRODUCT('DCF Valuation'!$C$13:$G$13,1/(1+$B10)^{1,2,3,4,5})+('DCF Valuation'!$G$13*(1+E$7))/($B10-E$7)/(1+$B10)^5-'DCF Valuation'!$C$27)/'DCF Valuation'!$C$29 -> 2250.5643 | F10: =(SUMPRODUCT('DCF Valuation'!$C$13:$G$13,1/(1+$B10)^{1,2,3,4,5})+('DCF Valuation'!$G$13*(1+F$7))/($B10-F$7)/(1+$B10)^5-'DCF Valuation'!$C$27)/'DCF Valuation'!$C$29 -> 2598.9795 | G10: =(SUMPRODUCT('DCF Valuation'!$C$13:$G$13,1/(1+$B10)^{1,2,3,4,5})+('DCF Valuation'!$G$13*(1+G$7))/($B10-G$7)/(1+$B10)^5-'DCF Valuation'!$C$27)/'DCF Valuation'!$C$29 -> 3121.6023
B11: 0.12 | C11: =(SUMPRODUCT('DCF Valuation'!$C$13:$G$13,1/(1+$B11)^{1,2,3,4,5})+('DCF Valuation'!$G$13*(1+C$7))/($B11-C$7)/(1+$B11)^5-'DCF Valuation'!$C$27)/'DCF Valuation'!$C$29 -> 1620.0278 | D11: =(SUMPRODUCT('DCF Valuation'!$C$13:$G$13,1/(1+$B11)^{1,2,3,4,5})+('DCF Valuation'!$G$13*(1+D$7))/($B11-D$7)/(1+$B11)^5-'DCF Valuation'!$C$27)/'DCF Valuation'!$C$29 -> 1760.0851 | E11: =(SUMPRODUCT('DCF Valuation'!$C$13:$G$13,1/(1+$B11)^{1,2,3,4,5})+('DCF Valuation'!$G$13*(1+E$7))/($B11-E$7)/(1+$B11)^5-'DCF Valuation'!$C$27)/'DCF Valuation'!$C$29 -> 1940.1587 | F11: =(SUMPRODUCT('DCF Valuation'!$C$13:$G$13,1/(1+$B11)^{1,2,3,4,5})+('DCF Valuation'!$G$13*(1+F$7))/($B11-F$7)/(1+$B11)^5-'DCF Valuation'!$C$27)/'DCF Valuation'!$C$29 -> 2180.2569 | G11: =(SUMPRODUCT('DCF Valuation'!$C$13:$G$13,1/(1+$B11)^{1,2,3,4,5})+('DCF Valuation'!$G$13*(1+G$7))/($B11-G$7)/(1+$B11)^5-'DCF Valuation'!$C$27)/'DCF Valuation'!$C$29 -> 2516.3944
B12: 0.13 | C12: =(SUMPRODUCT('DCF Valuation'!$C$13:$G$13,1/(1+$B12)^{1,2,3,4,5})+('DCF Valuation'!$G$13*(1+C$7))/($B12-C$7)/(1+$B12)^5-'DCF Valuation'!$C$27)/'DCF Valuation'!$C$29 -> 1464.147 | D12: =(SUMPRODUCT('DCF Valuation'!$C$13:$G$13,1/(1+$B12)^{1,2,3,4,5})+('DCF Valuation'!$G$13*(1+D$7))/($B12-D$7)/(1+$B12)^5-'DCF Valuation'!$C$27)/'DCF Valuation'!$C$29 -> 1572.2789 | E12: =(SUMPRODUCT('DCF Valuation'!$C$13:$G$13,1/(1+$B12)^{1,2,3,4,5})+('DCF Valuation'!$G$13*(1+E$7))/($B12-E$7)/(1+$B12)^5-'DCF Valuation'!$C$27)/'DCF Valuation'!$C$29 -> 1707.4439 | F12: =(SUMPRODUCT('DCF Valuation'!$C$13:$G$13,1/(1+$B12)^{1,2,3,4,5})+('DCF Valuation'!$G$13*(1+F$7))/($B12-F$7)/(1+$B12)^5-'DCF Valuation'!$C$27)/'DCF Valuation'!$C$29 -> 1881.2274 | G12: =(SUMPRODUCT('DCF Valuation'!$C$13:$G$13,1/(1+$B12)^{1,2,3,4,5})+('DCF Valuation'!$G$13*(1+G$7))/($B12-G$7)/(1+$B12)^5-'DCF Valuation'!$C$27)/'DCF Valuation'!$C$29 -> 2112.9387
B14: Current share price for reference: | C14: ='DCF Valuation'!$C$31 -> 5171
B16: Base case (WACC 11%, g 5%) is highlighted in yellow above and matches the 'DCF Valuation' tab.
B17: Interpretation: the implied share price is highly sensitive to the terminal growth assumption because ~most of Britannia's DCF value sits in the terminal value (a common feature of mature, high-ROCE FMCG businesses). Small changes in WACC or g materially move the valuation range.
B20: SENSITIVITY: FY27E Revenue Growth (rows) vs. FY31E EBITDA Margin (columns) — directional, holding WACC=11%, g=5%
B21: Note: this table is illustrative and shows the FCF sensitivity, not fully re-linked to the 3-Statement Model (which would require iterative recalculation). To test actual scenarios, edit the yellow assumption cells directly on the '3-Statement Model' tab and re-read the 'DCF Valuation' tab output.

Sheet Valuation Summary
B2: Valuation Summary & Conclusion — Britannia Industries Ltd
B3: Cross-check of relative (comps-based) and intrinsic (DCF-based) valuation methods
B5: Method | C5: Multiple / Basis Applied | D5: Applied to | E5: Implied Equity Value (₹ Cr) | F5: Implied Price / Share (₹) | G5: Current Price (₹) | H5: Upside / (Downside)
B6: EV/EBITDA — Peer Average | C6: =Comps!M15 -> 33.501102 | D6: =Comps!D7 -> 3514 | E6: =C6*D6-Comps!K7 -> 119952.87 | F6: =E6/Comps!I7 -> 4998.0363 | G6: ='DCF Valuation'!C31 -> 5171 | H6: =F6/G6-1 -> -0.033448787
B7: EV/EBITDA — Peer Median | C7: =Comps!M16 -> 33.567049 | D7: =Comps!D7 -> 3514 | E7: =C7*D7-Comps!K7 -> 120184.61 | F7: =E7/Comps!I7 -> 5007.6922 | G7: ='DCF Valuation'!C31 -> 5171 | H7: =F7/G7-1 -> -0.031581482
B8: P/E — Peer Average | C8: =Comps!N15 -> 47.681821 | D8: =Comps!H7 -> 105.18 | E8: n/a | F8: =C8*D8 -> 5015.1739 | G8: ='DCF Valuation'!C31 -> 5171 | H8: =F8/G8-1 -> -0.030134617
B9: P/E — Peer Median | C9: =Comps!N16 -> 48.609976 | D9: =Comps!H7 -> 105.18 | E9: n/a | F9: =C9*D9 -> 5112.7972 | G9: ='DCF Valuation'!C31 -> 5171 | H9: =F9/G9-1 -> -0.011255612
B10: P/B — Peer Average* | C10: =Comps!P15 -> 16.52849 | D10: =Comps!O7 -> 212 | E10: n/a | F10: =C10*D10 -> 3504.0398 | G10: ='DCF Valuation'!C31 -> 5171 | H10: =F10/G10-1 -> -0.32236709
B11: P/B — Peer Median* | C11: =Comps!P16 -> 8.3698333 | D11: =Comps!O7 -> 212 | E11: n/a | F11: =C11*D11 -> 1774.4047 | G11: ='DCF Valuation'!C31 -> 5171 | H11: =F11/G11-1 -> -0.65685464
B12: DCF — Base Case (WACC 11%, g 5%) | C12: n/a | D12: n/a | E12: n/a | F12: ='DCF Valuation'!C30 -> 2250.5643 | G12: ='DCF Valuation'!C31 -> 5171 | H12: =F12/G12-1 -> -0.56477195
B14: Simple Average — All Methods | F14: =AVERAGE(F6:F12) -> 3951.8155 | G14: ='DCF Valuation'!C31 -> 5171 | H14: =F14/G14-1 -> -0.23577345
B15: Simple Average — Excl. P/B & DCF** | F15: =AVERAGE(F6:F9) -> 5033.4249 | G15: ='DCF Valuation'!C31 -> 5171 | H15: =F15/G15-1 -> -0.026605124
B18: * P/B comparison is distorted by wide ROE differences across peers (e.g. Nestlé India's 73% ROE supports a 52x P/B) and is shown for completeness but weighted less heavily in the conclusion.
B19: ** Excludes P/B (distorted by ROE dispersion) and DCF (most sensitive to long-run assumptions); reflects EV/EBITDA and P/E only, the two most comparable relative metrics across this peer set.
B21: CONCLUSION
B22: Relative valuation: Britannia trades at ~34.8x EV/EBITDA and ~49.1x P/E (FY26A), versus a 7-company FMCG peer average of ~33.5x EV/EBITDA and ~47.7x P/E. On these two metrics Britannia is roughly IN LINE WITH, TO MODESTLY ABOVE, peer averages (a premium of ~4% on EV/EBITDA and ~3% on P/E) — not a large gap given the diversity of the peer set (e.g. ITC's low multiples reflect its tobacco/diversified mix; Nestlé's very high multiples reflect its exceptional ~73% ROE). On P/B, Britannia (24.5x) screens well above the peer average (16.5x) and median (8.4x), but this is partly explained by its high ROE (53.6%) relative to most peers, so the P/B gap is not, by itself, strong evidence of overvaluation. Intrinsic (DCF) valuation: Using a base-case 5-year FCF projection (revenue growth moderating from 9% to 7%, EBITDA margin expanding from 18.5% to 19.5%, WACC of 11%, and a 5% terminal growth rate), the DCF implies a fair value of roughly ₹2,250/share — well below the current market price of ₹5,171/share (a ~56% gap). The sensitivity table shows this conclusion is highly dependent on WACC and terminal growth: only under a bullish combination (WACC ~9%, terminal growth ~7%) does the DCF value approach the current price. Because ~76% of the DCF's enterprise value sits in the terminal value, small changes in these long-run assumptions swing the result substantially — a common feature of high-quality, high-multiple compounders. Overall: on a PURE RELATIVE (peer multiple) basis, Britannia looks FAIRLY VALUED to MODESTLY OVERVALUED versus FMCG peers. On a CONSERVATIVE INTRINSIC (DCF) basis, the stock appears OVERVALUED unless the market's more optimistic long-term growth/margin/cost-of-capital assumptions are accepted. This combination is consistent with a stock priced for continued premiumisation, market-share gains, and margin expansion well beyond what the explicit 5-year forecast captures — i.e., the market is paying up for growth durability, not for current-year fundamentals. A prospective investor's conclusion should hinge on conviction in Britannia sustaining high-single-digit revenue growth AND ~19-20% EBITDA margins for a decade or more, not just the next five years.
B42: Tools / Methods used: Excel (openpyxl + formulas), Comparable Company Analysis, 3-Statement Financial Modeling, Discounted Cash Flow, Sensitivity (Data Table) Analysis.
